<?xml version="1.0" ?>
<!-- =================================================================================== -->
<!-- |    This document was autogenerated by xacro from mybot.xacro                    | -->
<!-- |    EDITING THIS FILE BY HAND IS NOT RECOMMENDED                                 | -->
<!-- =================================================================================== -->
<robot name="myrobot">
  <!--Differential drive controller-->
  <gazebo>
    <plugin filename="libgazebo_ros_diff_drive.so" name="differential_drive_controller">
      <legacyMode>false</legacyMode>
      <alwaysOn>true</alwaysOn>
      <updateRate>10</updateRate>
      <leftJoint>left_wheel_hinge</leftJoint>
      <rightJoint>right_wheel_hinge</rightJoint>
      <wheelSeparation>0.4</wheelSeparation>
      <wheelDiameter>0.2</wheelDiameter>
      <torque>10000</torque>
      <commandTopic>cmd_vel</commandTopic>
      <odometryTopic>odom</odometryTopic>
      <odometryFrame>odom</odometryFrame>
      <robotBaseFrame>chassis</robotBaseFrame>
      <rosDebugLevel>na</rosDebugLevel>
      <publishWheelTF>false</publishWheelTF>
      <publishOdomTF>true</publishOdomTF>
      <publishWheelJointState>false</publishWheelJointState>
      <wheelAcceleration>0</wheelAcceleration>
      <wheelTorque>5</wheelTorque>
      <publishTf>true</publishTf>
      <odometrySource>world</odometrySource>
    </plugin>
  </gazebo>
  <gazebo reference="base_link">
    <material>Gazebo/Orange</material>
    <mu1 value="0.0"/>
    <mu2 value="0.0"/>
  </gazebo>
  <gazebo reference="right_wheel">
    <material>Gazebo/FlatBlack</material>
  </gazebo>
  <gazebo reference="left_wheel">
    <material>Gazebo/FlatBlack</material>
  </gazebo>
  <!--Camera-->
  <gazebo reference="camera">
    <material>Gazebo/Green</material>
    <sensor name="camera1" type="camera">
      <update_rate>30.0</update_rate>
      <camera name="head">
        <horizontal_fov>1.3962634</horizontal_fov>
        <image>
          <width>800</width>
          <height>800</height>
          <format>R8G8B8</format>
        </image>
        <clip>
          <near>0.02</near>
          <far>300</far>
        </clip>
      </camera>
      <plugin filename="libgazebo_ros_camera.so" name="camera_controller">
        <alwaysOn>true</alwaysOn>
        <updateRate>0.0</updateRate>
        <cameraName>mybot/camera1</cameraName>
        <imageTopicName>image_raw</imageTopicName>
        <cameraInfoTopicName>camera_info</cameraInfoTopicName>
        <frameName>camera</frameName>
        <hackBaseline>0.07</hackBaseline>
        <distortionK1>0.0</distortionK1>
        <distortionK2>0.0</distortionK2>
        <distortionK3>0.0</distortionK3>
        <distortionT1>0.0</distortionT1>
        <distortionT2>0.0</distortionT2>
      </plugin>
    </sensor>
  </gazebo>
  <!-- Hokuyo Laser Scan -->
  <gazebo reference="hokuyo">
    <sensor name="head_hokuyo_sensor" type="gpu_ray">
      <pose>0 0 0 0 0 0</pose>
      <visualize>true</visualize>
      <update_rate>40</update_rate>
      <ray>
        <scan>
          <horizontal>
            <samples>720</samples>
            <resolution>1</resolution>
            <min_angle>-1.570796</min_angle>
            <max_angle>1.570796</max_angle>
          </horizontal>
        </scan>
        <range>
          <min>0.10</min>
          <max>30.0</max>
          <resolution>0.01</resolution>
        </range>
        <noise>
          <type>gaussian</type>
          <!-- Noise parameters based on published spec for Hokuyo laser
               achieving "+-30mm" accuracy at range < 10m.  A mean of 0.0m and
               stddev of 0.01m will put 99.7% of samples within 0.03m of the true
               reading. -->
          <mean>0.0</mean>
          <stddev>0.01</stddev>
        </noise>
      </ray>
      <plugin filename="libgazebo_ros_gpu_laser.so" name="gazebo_ros_head_hokuyo_controller">
        <topicName>/mybot/laser/scan</topicName>
        <frameName>hokuyo</frameName>
      </plugin>
    </sensor>
  </gazebo>
  <material name="black">
    <color rgba="0.0 0.0 0.0 1.0"/>
  </material>
  <material name="blue">
    <color rgba="0.0 0.0 0.8 1.0"/>
  </material>
  <material name="green">
    <color rgba="0.0 0.8 0.0 1.0"/>
  </material>
  <material name="grey">
    <color rgba="0.2 0.2 0.2 1.0"/>
  </material>
  <material name="orange">
    <color rgba="1.0 0.4235294117647059 0.0392156862745098 1.0"/>
  </material>
  <material name="brown">
    <color rgba="0.8705882352941177 0.8117647058823529 0.7647058823529411 1.0"/>
  </material>
  <material name="red">
    <color rgba="0.8 0.0 0.0 1.0"/>
  </material>
  <material name="white">
    <color rgba="1.0 1.0 1.0 1.0"/>
  </material>
  <!--Dummy base link-->
  <link name="chassis"/>
  <joint name="base_link_to_base" type="fixed">
    <parent link="chassis"/>
    <child link="base_link"/>
    <origin rpy="0.0 0 0" xyz="0 0 0"/>
  </joint>
  <!--Base Link-->
  <link name="base_link">
    <inertial>
      <mass value="9.8129"/>
      <origin rpy="0 0 0" xyz="-0.00636873 0.00030011 0.0767722"/>
      <inertia ixx="1.0087" ixy="-6.05459e-06" ixz="-0.0112309" iyy="11.3554" iyz="-0.000118317" izz="0.684012"/>
    </inertial>
    <collision name="collision">
      <origin rpy="-1.5708 6.7993e-17 1.5737e-17" xyz="-0.00412574 0.000222774 -0.115845"/>
      <geometry>
        <mesh filename="package://bookbot/meshes/base_1_supporto.stl"/>
      </geometry>
      <surface>
        <friction>
          <ode>
            <mu>0</mu>
            <mu2>0</mu2>
            <slip1>1.0</slip1>
            <slip2>1.0</slip2>
          </ode>
        </friction>
      </surface>
    </collision>
    <visual name="base_link_visual">
      <origin rpy="-1.5708 6.7993e-17 1.5737e-17" xyz="-0.00412574 0.000222774 -0.115845"/>
      <geometry>
        <mesh filename="package://bookbot/meshes/base_1_supporto.stl"/>
      </geometry>
    </visual>
  </link>
  <!--Left Standard Fixed Wheel-->
  <link name="left_wheel">
    <collision name="collision">
      <origin rpy="-3.14159 -0 0" xyz="0 0 0.025"/>
      <geometry>
        <mesh filename="package://bookbot/meshes/wheel.stl"/>
      </geometry>
    </collision>
    <visual name="left_wheel_visual">
      <origin rpy="-3.14159 -0 0" xyz="0 0 0.025"/>
      <geometry>
        <mesh filename="package://bookbot/meshes/wheel.stl"/>
      </geometry>
    </visual>
    <inertial>
      <origin rpy="0 0 0" xyz="-2.18305e-18 5.73556e-20 -3.46945e-18"/>
      <mass value="3.98738"/>
      <inertia ixx="0.0106447" ixy="0" ixz="0" iyy="0.0106447" iyz="3.93411e-35" izz="0.0197122"/>
    </inertial>
  </link>
  <joint name="left_wheel_hinge" type="continuous">
    <origin rpy="-1.5708 1.5708 0" xyz="0.096678 0.204146 -0.0808453"/>
    <child link="left_wheel"/>
    <parent link="base_link"/>
    <axis rpy="0 0 0" xyz="0 0 1"/>
    <limit effort="10000" velocity="1000"/>
    <joint_properties damping="1.0" friction="1.0"/>
  </joint>
  <!--Right Standard Fixed Wheel-->
  <link name="right_wheel">
    <collision name="collision">
      <origin rpy="3.14159 -0 0" xyz="0 0 0.025"/>
      <geometry>
        <mesh filename="package://bookbot/meshes/wheel.stl"/>
      </geometry>
    </collision>
    <visual name="right_wheel_visual">
      <origin rpy="3.14159 -0 0" xyz="0 0 0.025"/>
      <geometry>
        <mesh filename="package://bookbot/meshes/wheel.stl"/>
      </geometry>
    </visual>
    <inertial>
      <origin rpy="0 0 0" xyz="-2.18305e-18 5.73556e-20 2.42861e-17"/>
      <mass value="3.98738"/>
      <inertia ixx="0.0106447" ixy="0" ixz="0" iyy="0.0106447" iyz="-7.11867e-35" izz="0.0197122"/>
    </inertial>
  </link>
  <joint name="right_wheel_hinge" type="continuous">
    <origin rpy="-1.5708 1.5708 0" xyz="0.096678 -0.2037 -0.0808453"/>
    <child link="right_wheel"/>
    <parent link="base_link"/>
    <axis rpy="0 0 0" xyz="0 0 1"/>
    <limit effort="10000" velocity="1000"/>
    <joint_properties damping="1.0" friction="1.0"/>
  </joint>
  <!--Camera-->
  <link name="camera">
    <collision>
      <origin rpy="0 0 0" xyz="0 0 0"/>
      <geometry>
        <box size="0.05 0.05 0.05"/>
      </geometry>
    </collision>
    <visual>
      <origin rpy="0 0 0" xyz="0 0 0"/>
      <geometry>
        <box size="0.05 0.05 0.05"/>
      </geometry>
      <material name="green"/>
    </visual>
    <inertial>
      <mass value="0.1"/>
      <origin rpy="0 0 0" xyz="0 0 0"/>
      <box_inertia m="0.1" x="0.05" y="0.05" z="0.05"/>
      <inertia ixx="1e-6" ixy="0" ixz="0" iyy="1e-6" iyz="0" izz="1e-6"/>
    </inertial>
  </link>
  <joint name="camera_joint" type="fixed">
    <axis xyz="0 1 0"/>
    <origin rpy="0 0 0" xyz=".25 0 0.24"/>
    <parent link="chassis"/>
    <child link="camera"/>
  </joint>
  <joint name="hokuyo_joint" type="fixed">
    <axis xyz="0 1 0"/>
    <origin rpy="0 0 0" xyz=".25 0 0.44"/>
    <parent link="base_link"/>
    <child link="hokuyo"/>
  </joint>
  <!-- Hokuyo Laser -->
  <link name="hokuyo">
    <collision>
      <origin rpy="0 0 0" xyz="0 0 0"/>
      <geometry>
        <box size="0.1 0.1 0.1"/>
      </geometry>
    </collision>
    <visual>
      <origin rpy="0 0 0" xyz="0 0 0"/>
      <geometry>
        <mesh filename="package://bookbot/meshes/hokuyo.dae"/>
      </geometry>
    </visual>
    <inertial>
      <mass value="1e-5"/>
      <origin rpy="0 0 0" xyz="0 0 0"/>
      <inertia ixx="1e-6" ixy="0" ixz="0" iyy="1e-6" iyz="0" izz="1e-6"/>
    </inertial>
  </link>
</robot>

