<?xml version='1.0'?>

<robot name="myrobot" xmlns:xacro="http://www.ros.org/wiki/xacro">

  <xacro:property name="cameraSize" value="0.05"/>
  <xacro:property name="cameraMass" value="0.1"/>

  <xacro:include filename="$(find bookbot)/urdf/mybot.gazebo" />
  <xacro:include filename="$(find bookbot)/urdf/materials.xacro" />

  <!--Dummy base link-->
  <link name="chassis"></link>
  

  <joint name="base_link_to_base" type="fixed">
    <parent link="chassis"/>
    <child link="base_link" />
    <origin rpy="0.0 0 0" xyz="0 0 0"/>
  </joint>
  
  <!--Base Link-->
  <link name='base_link'>
    <inertial>
    <mass value="9.8129" />
    <origin xyz="-0.00636873 0.00030011 0.0767722" rpy="0 0 0"/>
    <inertia
      ixx="1.0087" ixy="-6.05459e-06" ixz="-0.0112309" iyy="11.3554" iyz="-0.000118317" izz="0.684012"/>
    </inertial>

    <collision name='collision'>
      <origin xyz="-0.00412574 0.000222774 -0.115845" rpy="-1.5708 6.7993e-17 1.5737e-17" />
      <geometry>
      <mesh filename="package://bookbot/meshes/base_1_supporto.stl" />
      
      </geometry>
      <surface>
        <friction>
        <ode>
          <mu>0</mu>
          <mu2>0</mu2>
          <slip1>1.0</slip1>
          <slip2>1.0</slip2>
        </ode>
        </friction>
      </surface>
    </collision>

    <visual name='base_link_visual'>
      <origin xyz="-0.00412574 0.000222774 -0.115845" rpy="-1.5708 6.7993e-17 1.5737e-17" />
      <geometry>
        <mesh filename="package://bookbot/meshes/base_1_supporto.stl" />
      </geometry>
    </visual>
    
    
  </link>
  <!--Left Standard Fixed Wheel-->
  <link name="left_wheel">
    <collision name="collision">
      <origin xyz="0 0 0.025" rpy="-3.14159 -0 0" />
      <geometry>
        <mesh filename="package://bookbot/meshes/wheel.stl" />
      </geometry>
    </collision>
    <visual name="left_wheel_visual">
      <origin xyz="0 0 0.025" rpy="-3.14159 -0 0" />
      <geometry>
      <mesh filename="package://bookbot/meshes/wheel.stl" />
      </geometry>
    </visual>
    <inertial>
      <origin xyz="-2.18305e-18 5.73556e-20 -3.46945e-18" rpy="0 0 0"/>
      <mass value="3.98738" />
      <inertia
        ixx="0.0106447" ixy="0"  ixz="0" iyy="0.0106447" iyz="3.93411e-35" izz="0.0197122"/>
    </inertial>
  </link>

  <joint type="continuous" name="left_wheel_hinge">
    <origin xyz="0.096678 0.204146 -0.0808453" rpy="-1.5708 1.5708 0" />
    <child link="left_wheel"/>
    <parent link="base_link"/>
    <axis xyz="0 0 1" rpy="0 0 0"/>
    <limit effort="10000" velocity="1000"/>
    <joint_properties damping="1.0" friction="1.0"/>
  </joint>

  <!--Right Standard Fixed Wheel-->
  <link name="right_wheel">
    <collision name="collision">
      <origin xyz="0 0 0.025" rpy="3.14159 -0 0" />
      <geometry>
        <mesh filename="package://bookbot/meshes/wheel.stl"/>
      </geometry>
    </collision>
    <visual name="right_wheel_visual">
      <origin xyz="0 0 0.025" rpy="3.14159 -0 0" />
      <geometry>
        <mesh filename="package://bookbot/meshes/wheel.stl"/>
      </geometry>
    </visual>
    <inertial>
      <origin xyz="-2.18305e-18 5.73556e-20 2.42861e-17" rpy="0 0 0"/>
      <mass value="3.98738" />
      <inertia
        ixx="0.0106447" ixy="0"  ixz="0" iyy="0.0106447" iyz="-7.11867e-35" izz="0.0197122"/>
    </inertial>
  </link>

  <joint type="continuous" name="right_wheel_hinge">
    
    <origin xyz="0.096678 -0.2037 -0.0808453" rpy="-1.5708 1.5708 0" />
    <child link="right_wheel"/>
    <parent link="base_link"/>
    <axis xyz="0 0 1" rpy="0 0 0"/>
    <limit effort="10000" velocity="1000"/>
    <joint_properties damping="1.0" friction="1.0"/>
  </joint>

  
  <!--Camera-->
  <link name="camera">
    <collision>
      <origin xyz="0 0 0" rpy="0 0 0"/>
      <geometry>
        <box size="${cameraSize} ${cameraSize} ${cameraSize}"/>
      </geometry>
    </collision>

    <visual>
      <origin xyz="0 0 0" rpy="0 0 0"/>
      <geometry>
        <box size="${cameraSize} ${cameraSize} ${cameraSize}"/>
      </geometry>
      <material name="green"/>
    </visual>

    <inertial>
      <mass value="${cameraMass}" />
      <origin xyz="0 0 0" rpy="0 0 0"/>
      <box_inertia m="${cameraMass}" x="${cameraSize}" y="${cameraSize}" z="${cameraSize}" />
      <inertia ixx="1e-6" ixy="0" ixz="0" iyy="1e-6" iyz="0" izz="1e-6" />
    </inertial>
  </link>

  <joint name="camera_joint" type="fixed">
    <axis xyz="0 1 0" />
    <origin xyz=".25 0 0.24" rpy="0 0 0"/>
    <parent link="chassis"/>
    <child link="camera"/>
  </joint>

  <joint name="hokuyo_joint" type="fixed">
    <axis xyz="0 1 0" />
    <origin xyz=".25 0 0.44" rpy="0 0 0"/>
    <parent link="base_link"/>
    <child link="hokuyo"/>
  </joint>

  <!-- Hokuyo Laser -->
  <link name="hokuyo">
    <collision>
      <origin xyz="0 0 0" rpy="0 0 0"/>
      <geometry>
        <box size="0.1 0.1 0.1"/>
      </geometry>
    </collision>

    <visual>
      <origin xyz="0 0 0" rpy="0 0 0"/>
      <geometry>
        <mesh filename="package://bookbot/meshes/hokuyo.dae"/>
      </geometry>
    </visual>

    <inertial>
      <mass value="1e-5" />
      <origin xyz="0 0 0" rpy="0 0 0"/>
      <inertia ixx="1e-6" ixy="0" ixz="0" iyy="1e-6" iyz="0" izz="1e-6" />
    </inertial>
  </link>

</robot>